import {
	createPrintContactRecordRequest,
	SalesforceError,
	salesforceErrorCodes,
	SalesforceService,
} from '../services/salesforce';
import { printSubscriber, street } from './fixtures/salesforceFixtures';

describe('SalesforceService', () => {
	test('createPrintContactRecordRequest should have properties populated correctly', () => {
		const newContact = createPrintContactRecordRequest(printSubscriber);

		expect(newContact.MailingStreet).toBe(street);
		expect(newContact.MailingCity).toBe(printSubscriber.deliveryAddress.city);
		expect(newContact.MailingState).toBe(printSubscriber.deliveryAddress.state);
		expect(newContact.MailingPostalCode).toBe(
			printSubscriber.deliveryAddress.postCode,
		);
		expect(newContact.MailingCountry).toBe('United Kingdom');

		expect(newContact.OtherStreet).toBe(street);
		expect(newContact.OtherCity).toBe(printSubscriber.billingAddress.city);
		expect(newContact.OtherState).toBe(printSubscriber.billingAddress.state);
		expect(newContact.OtherPostalCode).toBe(
			printSubscriber.billingAddress.postCode,
		);
		expect(newContact.OtherCountry).toBe('United Kingdom');

		expect(newContact.Email).toBe(printSubscriber.primaryEmailAddress);
		expect(newContact.FirstName).toBe(printSubscriber.firstName);
		expect(newContact.LastName).toBe(printSubscriber.lastName);
		expect(newContact.Salutation).toBe(printSubscriber.title);
		expect(newContact.Phone).toBe(printSubscriber.telephoneNumber);
	});

	test('it should throw an INSERT_UPDATE_DELETE_NOT_ALLOWED_DURING_MAINTENANCE error when appropriate', () => {
		const errorString =
			'Failed Upsert of new Contact: Upsert failed. First exception on row 0; first error: INSERT_UPDATE_DELETE_NOT_ALLOWED_DURING_MAINTENANCE, Updates canâ€™t be made during maintenance. Try again when maintenance is complete: []';

		expect(() =>
			SalesforceService.parseResponseToResult({
				Success: false,
				ErrorString: errorString,
			}),
		).toThrow(
			new SalesforceError({
				errorCode: salesforceErrorCodes.readOnlyMaintenance,
				message: errorString,
			}),
		);
	});
	test('it should throw an UNKNOWN_ERROR error for all other exceptions', () => {
		const errorString = 'Things have gone awry';

		expect(() =>
			SalesforceService.parseResponseToResult({
				Success: false,
				ErrorString: errorString,
			}),
		).toThrow(
			new SalesforceError({
				errorCode: 'UNKNOWN_ERROR',
				message: errorString,
			}),
		);
	});
});
